[WARNING] 2025-07-28 05:53:10,334 apps.users.helper: 123
[WARNING] 2025-07-28 17:36:28,291 django.request: Not Found: /
[WARNING] 2025-07-28 17:36:34,011 django.request: Not Found: /static/graphene_django/graphiql.js
[WARNING] 2025-07-28 17:36:34,084 django.request: Not Found: /static/graphene_django/graphiql.js
[WARNING] 2025-07-28 17:36:37,210 django.request: Not Found: /static/graphene_django/graphiql.js
[WARNING] 2025-07-28 17:36:37,267 django.request: Not Found: /static/graphene_django/graphiql.js
[WARNING] 2025-07-28 17:40:59,849 django.request: Not Found: /static/graphene_django/graphiql.js
[WARNING] 2025-07-28 17:40:59,924 django.request: Not Found: /static/graphene_django/graphiql.js
[WARNING] 2025-07-28 17:42:02,550 django.request: Not Found: /static/graphene_django/graphiql.js
[WARNING] 2025-07-28 17:42:02,608 django.request: Not Found: /static/graphene_django/graphiql.js
[WARNING] 2025-07-28 17:42:06,314 django.request: Not Found: /static/graphene_django/graphiql.js
[WARNING] 2025-07-28 17:42:06,371 django.request: Not Found: /static/graphene_django/graphiql.js
[WARNING] 2025-07-28 18:06:16,962 django.request: Bad Request: /graphql/
[WARNING] 2025-07-28 18:06:22,644 django.request: Bad Request: /graphql/
[WARNING] 2025-07-28 18:10:54,184 django.request: Bad Request: /graphql/
[WARNING] 2025-07-28 18:22:04,152 django.request: Bad Request: /graphql/
[WARNING] 2025-07-28 18:22:11,126 django.request: Bad Request: /graphql/
[WARNING] 2025-07-28 18:22:22,088 django.request: Bad Request: /graphql/
[WARNING] 2025-07-28 18:22:25,187 django.request: Bad Request: /graphql/
[WARNING] 2025-07-28 20:07:02,518 django.request: Bad Request: /graphql/
[WARNING] 2025-07-28 20:07:13,530 django.request: Bad Request: /graphql/
[ERROR] 2025-07-28 20:19:26,512 django.request: Internal Server Error: /graphql/
Traceback (most recent call last):
  File "/app/.venv/lib/python3.13/site-packages/asgiref/sync.py", line 518, in thread_handler
    raise exc_info[1]
  File "/app/.venv/lib/python3.13/site-packages/django/core/handlers/exception.py", line 42, in inner
    response = await get_response(request)
               ^^^^^^^^^^^^^^^^^^^^^^^^^^^
  File "/app/.venv/lib/python3.13/site-packages/asgiref/sync.py", line 518, in thread_handler
    raise exc_info[1]
  File "/app/.venv/lib/python3.13/site-packages/django/core/handlers/base.py", line 253, in _get_response_async
    response = await wrapped_callback(
               ^^^^^^^^^^^^^^^^^^^^^^^
        request, *callback_args, **callback_kwargs
        ^^^^^^^^^^^^^^^^^^^^^^^^^^^^^^^^^^^^^^^^^^
    )
    ^
  File "/app/.venv/lib/python3.13/site-packages/asgiref/sync.py", line 468, in __call__
    ret = await asyncio.shield(exec_coro)
          ^^^^^^^^^^^^^^^^^^^^^^^^^^^^^^^
  File "/root/.local/share/uv/python/cpython-3.13.5-linux-x86_64-gnu/lib/python3.13/concurrent/futures/thread.py", line 59, in run
    result = self.fn(*self.args, **self.kwargs)
  File "/app/.venv/lib/python3.13/site-packages/asgiref/sync.py", line 522, in thread_handler
    return func(*args, **kwargs)
  File "/app/.venv/lib/python3.13/site-packages/django/views/decorators/csrf.py", line 65, in _view_wrapper
    return view_func(request, *args, **kwargs)
  File "/app/.venv/lib/python3.13/site-packages/django/views/generic/base.py", line 104, in view
    return self.dispatch(request, *args, **kwargs)
           ~~~~~~~~~~~~~^^^^^^^^^^^^^^^^^^^^^^^^^^
  File "/app/.venv/lib/python3.13/site-packages/django/utils/decorators.py", line 48, in _wrapper
    return bound_method(*args, **kwargs)
  File "/app/.venv/lib/python3.13/site-packages/django/utils/decorators.py", line 192, in _view_wrapper
    result = _process_exception(request, e)
  File "/app/.venv/lib/python3.13/site-packages/django/utils/decorators.py", line 190, in _view_wrapper
    response = view_func(request, *args, **kwargs)
  File "/app/.venv/lib/python3.13/site-packages/graphene_django/views.py", line 201, in dispatch
    result, status_code = self.get_response(request, data, show_graphiql)
                          ~~~~~~~~~~~~~~~~~^^^^^^^^^^^^^^^^^^^^^^^^^^^^^^
  File "/app/.venv/lib/python3.13/site-packages/graphene_django/views.py", line 229, in get_response
    if execution_result.errors:
       ^^^^^^^^^^^^^^^^^^^^^^^
AttributeError: 'coroutine' object has no attribute 'errors'
[WARNING] 2025-07-28 20:30:15,252 django.request: Bad Request: /graphql/
[WARNING] 2025-07-28 20:30:36,338 django.request: Bad Request: /graphql/
[ERROR] 2025-07-28 20:46:51,370 django.request: Internal Server Error: /graphql/
Traceback (most recent call last):
  File "/app/.venv/lib/python3.13/site-packages/asgiref/sync.py", line 518, in thread_handler
    raise exc_info[1]
  File "/app/.venv/lib/python3.13/site-packages/django/core/handlers/exception.py", line 42, in inner
    response = await get_response(request)
               ^^^^^^^^^^^^^^^^^^^^^^^^^^^
  File "/app/.venv/lib/python3.13/site-packages/asgiref/sync.py", line 518, in thread_handler
    raise exc_info[1]
  File "/app/.venv/lib/python3.13/site-packages/django/core/handlers/base.py", line 253, in _get_response_async
    response = await wrapped_callback(
               ^^^^^^^^^^^^^^^^^^^^^^^
        request, *callback_args, **callback_kwargs
        ^^^^^^^^^^^^^^^^^^^^^^^^^^^^^^^^^^^^^^^^^^
    )
    ^
  File "/app/.venv/lib/python3.13/site-packages/asgiref/sync.py", line 468, in __call__
    ret = await asyncio.shield(exec_coro)
          ^^^^^^^^^^^^^^^^^^^^^^^^^^^^^^^
  File "/root/.local/share/uv/python/cpython-3.13.5-linux-x86_64-gnu/lib/python3.13/concurrent/futures/thread.py", line 59, in run
    result = self.fn(*self.args, **self.kwargs)
  File "/app/.venv/lib/python3.13/site-packages/asgiref/sync.py", line 522, in thread_handler
    return func(*args, **kwargs)
  File "/app/.venv/lib/python3.13/site-packages/django/views/decorators/csrf.py", line 65, in _view_wrapper
    return view_func(request, *args, **kwargs)
  File "/app/.venv/lib/python3.13/site-packages/django/views/generic/base.py", line 104, in view
    return self.dispatch(request, *args, **kwargs)
           ~~~~~~~~~~~~~^^^^^^^^^^^^^^^^^^^^^^^^^^
  File "/app/.venv/lib/python3.13/site-packages/django/utils/decorators.py", line 48, in _wrapper
    return bound_method(*args, **kwargs)
  File "/app/.venv/lib/python3.13/site-packages/django/utils/decorators.py", line 192, in _view_wrapper
    result = _process_exception(request, e)
  File "/app/.venv/lib/python3.13/site-packages/django/utils/decorators.py", line 190, in _view_wrapper
    response = view_func(request, *args, **kwargs)
  File "/app/.venv/lib/python3.13/site-packages/graphene_django/views.py", line 201, in dispatch
    result, status_code = self.get_response(request, data, show_graphiql)
                          ~~~~~~~~~~~~~~~~~^^^^^^^^^^^^^^^^^^^^^^^^^^^^^^
  File "/app/.venv/lib/python3.13/site-packages/graphene_django/views.py", line 229, in get_response
    if execution_result.errors:
       ^^^^^^^^^^^^^^^^^^^^^^^
AttributeError: 'coroutine' object has no attribute 'errors'
[WARNING] 2025-07-29 00:46:26,449 django.request: Bad Request: /graphql/
[WARNING] 2025-07-29 00:46:34,272 django.request: Bad Request: /graphql/
[WARNING] 2025-07-29 00:59:02,558 django.request: Bad Request: /graphql/
[WARNING] 2025-07-29 00:59:06,010 django.request: Bad Request: /graphql/
[WARNING] 2025-07-29 00:59:13,874 django.request: Bad Request: /graphql/
[WARNING] 2025-07-29 00:59:41,035 django.request: Bad Request: /graphql/
[WARNING] 2025-07-29 01:24:21,530 django.request: Bad Request: /graphql/
[WARNING] 2025-07-29 01:30:54,270 django.request: Bad Request: /graphql/
[WARNING] 2025-07-29 01:31:03,825 django.request: Bad Request: /graphql/
[WARNING] 2025-07-29 01:31:05,011 django.request: Bad Request: /graphql/
[WARNING] 2025-07-29 01:31:30,693 django.request: Bad Request: /graphql/
[WARNING] 2025-07-29 01:31:35,029 django.request: Bad Request: /graphql/
[WARNING] 2025-07-29 01:32:10,428 django.request: Bad Request: /graphql/
[WARNING] 2025-07-29 01:33:58,114 django.request: Bad Request: /graphql/
[WARNING] 2025-07-29 01:34:15,893 django.request: Bad Request: /graphql/
[WARNING] 2025-07-29 01:34:23,990 django.request: Method Not Allowed: /graphql/
[WARNING] 2025-07-29 01:34:29,977 django.request: Bad Request: /graphql/
[WARNING] 2025-07-29 01:34:33,932 django.request: Bad Request: /graphql/
[WARNING] 2025-07-29 01:35:12,373 django.request: Bad Request: /graphql/
[WARNING] 2025-07-29 01:35:15,095 django.request: Bad Request: /graphql/
[WARNING] 2025-07-29 01:35:51,981 django.request: Bad Request: /graphql/
[WARNING] 2025-07-29 01:37:03,053 django.request: Bad Request: /graphql/
[WARNING] 2025-07-29 01:37:07,983 django.request: Bad Request: /graphql/
[WARNING] 2025-07-29 01:37:44,342 django.request: Bad Request: /graphql/
